<?xml version="1.0" ?>
<robot name="youbot">

  <material name="Orange">
    <color rgba="1.0 0.4 0.0 1.0"/>
  </material>
  <material name="Grey">
    <color rgba="0.7 0.7 0.7 1.0"/>
  </material>
  <material name="DarkGrey">
    <color rgba="0.3 0.3 0.3 1.0"/>
  </material>

  <link name="base_link">
    <visual>
      <origin rpy="0 0 3.14" xyz="0 0 0"/>
      <geometry>
        <mesh filename="package://youbot_model/mesh/base.stl"/>
      </geometry>
      <material name="Grey"/>
    </visual>
  </link>

  <link name="link1">
    <visual>
      <origin rpy="0 0 0" xyz="0 0 0"/>
      <geometry>
        <mesh filename="package://youbot_model/mesh/arm0.stl"/>
      </geometry>
      <material name="Orange"/>
    </visual>
  </link>

  <link name="link2">
    <visual>
    <!-- <origin xyz="0 -0.033 -0.246" /-->
    <origin xyz="0 0 0" rpy="0 0 0"/>
      <geometry>
        <mesh filename="package://youbot_model/mesh/arm1.stl"/>
      </geometry>
      <material name="Orange"/>
    </visual>
  </link>

  <link name="link3">
    <visual>
    <origin xyz="0 0 0" rpy="0 0 0"/>
      <geometry>
        <mesh filename="package://youbot_model/mesh/arm2.stl"/>
      </geometry>
      <material name="Orange"/>
    </visual>
  </link>

  <link name="link4">
    <visual>
    <origin xyz="0 0 0" rpy="0 0 0"/>
      <geometry>
        <mesh filename="package://youbot_model/mesh/arm3.stl"/>
      </geometry>
      <material name="Orange"/>
    </visual>
  </link>
  
  <link name="link5">
    <visual>
    <origin xyz="0 0 0" rpy="0 0 0"/>
      <geometry>
        <mesh filename="package://youbot_model/mesh/arm4.stl"/>
      </geometry>
      <material name="DarkGrey"/>
    </visual>
  </link>
  
  <link name="wheel_1_link">
    <visual>
      <origin xyz="0 0 0" rpy="0 0 0"/>
       <geometry>
        <mesh filename="package://youbot_model/mesh/wheel.stl"/>
      </geometry> 
      <material name="Orange"/>
    </visual>
  </link>  
  
  <link name="wheel_2_link">
    <visual>
      <origin xyz="0 0 0" rpy="0 0 0"/>
       <geometry>
        <mesh filename="package://youbot_model/mesh/wheel.stl"/>
      </geometry> 
      <material name="Orange"/>
    </visual>
  </link>  
  
  <link name="wheel_3_link">
    <visual>
      <origin xyz="0 0 0" rpy="0 0 0"/>
       <geometry>
        <mesh filename="package://youbot_model/mesh/wheel.stl"/>
      </geometry> 
      <material name="Orange"/>
    </visual>
  </link>
    
  <link name="wheel_4_link">
    <visual>
      <origin xyz="0 0 0" rpy="0 0 0"/>
       <geometry>
        <mesh filename="package://youbot_model/mesh/wheel.stl"/>
      </geometry> 
      <material name="Orange"/>
    </visual>
  </link>
  
  <link name="finger1_link">
    <visual>
      <origin xyz="0 0 0" />
      <geometry>
        <mesh filename="package://youbot_model/mesh/finger.stl"/>
      </geometry>
      <material name="DarkGrey"/>
    </visual>
  </link>
  
  
  <link name="finger2_link">
    <visual>
      <origin xyz="0 0 0" />
      <geometry>
        <mesh filename="package://youbot_model/mesh/finger.stl"/>
      </geometry>
      <material name="DarkGrey"/>
    </visual>
  </link>
  
<!--
    <Geom type="trimesh" modifiable="false">
      <Translation>0 0 0</Translation>
      <data>youBotGripperLeft.iv 1.0</data>
      <Render>youBotGripperLeft.iv 1.0</Render>
    </Geom>
    <Geom type="trimesh" modifiable="false">
      <Translation>0 0 0</Translation>
      <data>youBotGripperRight.iv 1.0</data>
      <Render>youBotGripperRight.iv 1.0</Render>
    </Geom>
-->
  <joint name="j0" type="continuous">
    <axis xyz="0 0 -1" />
    <origin xyz="0 -0.166 0.123" rpy="0 0 3.14"/>
    <!-- limit lower="170" higher="170" -->
    <parent link="base_link"/>
    <child link="link1"/>
  </joint>

  <joint name="j1" type="continuous">
    <parent link="link1"/>
    <child link="link2"/>
    <origin xyz="0 0.033 0.019" />
    <axis xyz="-1 0 0" />
    <!-- limitsdeg>-65 90</limitsdeg -->
  </joint>

  <joint name="j2" type="continuous">
    <parent link="link2"/>
    <child link="link3"/>
    <origin xyz="0 0 0.155" />
    <axis xyz="-1 0 0" />
    <!-- limitsdeg>-150 150</limitsdeg -->
  </joint>
  
  <joint name="j3" type="continuous">
    <parent link="link3"/>
    <child link="link4"/>
    <origin xyz="0 0 0.135" />
    <axis xyz="-1 0 0" />
    <!-- limitsdeg>-100 100</limitsdeg -->
  </joint>
  
  <joint name="j4" type="continuous">
    <parent link="link4"/>
    <child link="link5"/>
    <origin xyz="0 -0.002 0.131" />
    <axis xyz="0 0 -1" />
    <!-- limitsdeg>-165 165</limitsdeg -->
  </joint>

  <joint name="f1" type="prismatic">
    <parent link="link5"/>
    <child link="finger1_link"/>
    <origin xyz="-0.008 0.0 0.048" />
    <axis xyz="-1 0 0" />
  </joint>
  
  <joint name="f2" type="prismatic">
    <parent link="link5"/>
    <child link="finger2_link"/>
    <origin xyz="0.008 0.0 0.048" rpy="0 0 3.14"/>
    <axis xyz="-1 0 0" />
  </joint>

  <joint name="w3" type="continuous">
    <parent link="base_link"/>
    <child link="wheel_3_link"/>
    <origin xyz="0.158 0.228 -0.053" />
    <axis xyz="1 0 0" />
  </joint>
  
  <joint name="w4" type="continuous">
    <parent link="base_link"/>
    <child link="wheel_4_link"/>
    <origin xyz="-0.158 0.228 -0.053" rpy="0 3.14 0"/>
    <axis xyz="1 0 0" />
  </joint>
  
  <joint name="w2" type="continuous">
    <parent link="base_link"/>
    <child link="wheel_2_link"/>
    <origin xyz="0.158 -0.228 -0.053" rpy="0 3.14 0"/>
    <axis xyz="1 0 0" />
  </joint>
  
  <joint name="w1" type="continuous">
    <parent link="base_link"/>
    <child link="wheel_1_link"/>
    <origin xyz="-0.158 -0.228 -0.053" />
    <axis xyz="1 0 0" />
  </joint>

</robot>

